<?xml version="1.0" ?>
<robot name="cube">
    <link name="base_link">
        <inertial>
            <origin xyz="0 0 0.0" rpy="0 -0 0" />
            <mass value="1" />
            <inertia ixx="0.1" iyy="0.1" izz="0.1" ixy="0" ixz="0" iyz="0" />
        </inertial>
    </link>
    <link name="link1">
        <inertial>
            <origin xyz="0 0 0" rpy="0 -0 0" />
            <mass value="0.001" />
            <inertia ixx="0.001" iyy="0.001" izz="0.001" ixy="0" ixz="0" iyz="0" />
        </inertial>
    </link>
    <link name="link2">
        <inertial>
            <origin xyz="0 0 0" rpy="0 -0 0" />
            <mass value="0.001" />
            <inertia ixx="0.001" iyy="0.001" izz="0.001" ixy="0" ixz="0" iyz="0" />
        </inertial>
    </link>
    <link name="link3">
        <inertial>
            <origin xyz="0 0 0" rpy="0 -0 0" />
            <mass value="0.001" />
            <inertia ixx="0.001" iyy="0.001" izz="0.001" ixy="0" ixz="0" iyz="0" />
        </inertial>
    </link>
    <link name="link4">
        <inertial>
            <origin xyz="0 0 0" rpy="0 -0 0" />
            <mass value="0.001" />
            <inertia ixx="0.001" iyy="0.001" izz="0.001" ixy="0" ixz="0" iyz="0" />
        </inertial>
    </link>
    <link name="link5">
        <inertial>
            <origin xyz="0 0 0" rpy="0 -0 0" />
            <mass value="0.001" />
            <inertia ixx="0.001" iyy="0.001" izz="0.001" ixy="0" ixz="0" iyz="0" />
        </inertial>
    </link>
    <link name="object">
        <inertial>
            <origin xyz="0 0 0" rpy="0 0 0" />
            <mass value="1" />
            <inertia ixx="0.1" iyy="0.1" izz="0.1" ixy="0" ixz="0" iyz="0" />
        </inertial>
        <visual>
            <origin xyz="0 0 0" rpy="0 0 0" />
            <geometry>
                <mesh filename="./cube.obj" scale="1 1 1" />
            </geometry>
        </visual>
        <collision>
            <origin xyz="0 0 0" rpy="0 0 0" />
            <geometry>
                <box size="0.1 0.1 0.1"/>
            </geometry>
        </collision>
    </link>

    <joint name="j0" type="prismatic">
        <parent link="base_link" />
        <child link="link1" />
        <origin xyz="0.000000 0.000000 0.0" rpy="0.000000 0.000000 0.000000" />
        <axis xyz="1 0 0" />
        <limit lower="-2.967" upper="2.967" effort="176" velocity="1.7104" />
    </joint>
    <joint name="j1" type="prismatic">
        <parent link="link1" />
        <child link="link2" />
        <origin xyz="0.000000 0.000000 0.0" rpy="0.000000 0.000000 0.000000" />
        <axis xyz="0 1 0" />
        <limit lower="-2.967" upper="2.967" effort="176" velocity="1.7104" />
    </joint>
    <joint name="j2" type="prismatic">
        <parent link="link2" />
        <child link="link3" />
        <origin xyz="0.000000 0.000000 0.0" rpy="0.000000 0.000000 0.000000" />
        <axis xyz="0 0 1" />
        <limit lower="-2.0944" upper="2.0944" effort="176" velocity="1.7104" />
    </joint>
    <joint name="j3" type="revolute">
        <parent link="link3" />
        <child link="link4" />
        <origin xyz="0.000000 0.000000 0.0" rpy="0.000000 0.000000 0.000000" />
        <axis xyz="1 0 0" />
        <limit lower="-2.967" upper="2.967" effort="176" velocity="1.7104" />
    </joint>
    <joint name="j4" type="revolute">
        <parent link="link4" />
        <child link="link5" />
        <origin xyz="0.000000 0.000000 0.0" rpy="0.000000 0.000000 0.000000" />
        <axis xyz="0 1 0" />
        <limit lower="-2.967" upper="2.967" effort="176" velocity="1.7104" />
    </joint>
    <joint name="j5" type="revolute">
        <parent link="link5" />
        <child link="object" />
        <origin xyz="0.000000 0.000000 0.0" rpy="0.000000 0.000000 0.000000" />
        <axis xyz="0 0 1" />
        <limit lower="-2.0944" upper="2.0944" effort="176" velocity="1.7104" />
    </joint>
</robot>
